Workbook

Sheet Build your programme
A1: Build your programme
A2: The five core days are always included. Add any of the optional days by choosing Yes in the yellow cells: each one adds exactly one day. Your day-by-day programme below updates as you choose.
A4: Day | B4: Title | C4: What your team will be able to do | D4: Requires | E4: Include?
A5: The core · always included | H5: =$E$12 | I5: =IF(H5="Yes",1,0) | J5: Pre-course · Modern Java for Spring developers (pre-course bridge) | K5: Add-on days | L5: Bridge
A6: Day 1 | B6: From a plain-Java monolith to Spring Core | C6: Read a plain-Java monolith and name its problems, then hand its wiring to the Spring container: beans, injection, scopes, lifecycle, configuration, events and aspects. | D6: — | E6: Included | H6: Yes | I6: =I5+IF(H6="Yes",1,0) | J6: Core · From a plain-Java monolith to Spring Core | K6: Core Day 1 | L6: Core
A7: Day 2 | B7: Spring Boot, a REST API and PostgreSQL | C7: Turn the monolith into a Spring Boot application with its own starter, a REST API with one error contract and live documentation, and a PostgreSQL catalogue with migrations and localised data. | D7: — | E7: Included | H7: Yes | I7: =I6+IF(H7="Yes",1,0) | J7: Core · Spring Boot, a REST API and PostgreSQL | K7: Core Day 2 | L7: Core
A8: Day 3 | B8: Relationships, search, transactions and the safety net | C8: Model relationships that perform, add full-text search and facets, make checkout safe under concurrent load, and keep a test suite every module relies on. | D8: — | E8: Included | H8: Yes | I8: =I7+IF(H8="Yes",1,0) | J8: Core · Relationships, search, transactions and the safety net | K8: Core Day 3 | L8: Core
A9: Day 4 | B9: From monolith to microservices | C9: Split the monolith into services on PostgreSQL, MySQL and MongoDB that call each other, share configuration, find each other and sit behind one gateway. | D9: — | E9: Included | H9: Yes | I9: =I8+IF(H9="Yes",1,0) | J9: Core · From monolith to microservices | K9: Core Day 4 | L9: Core
A10: Day 5 | B10: Security: Spring Security, JWT, securing the system, and Keycloak | C10: Secure the system with Spring Security, JWT, ownership rules, service-to-service credentials and Keycloak. | D10: — | E10: Included | H10: Yes | I10: =I9+IF(H10="Yes",1,0) | J10: Core · Security: Spring Security, JWT, securing the system, and Keycloak | K10: Core Day 5 | L10: Core
A11: Optional add-on days · choose Yes or No | H11: =$E$13 | I11: =I10+IF(H11="Yes",1,0) | J11: Add-on 1 · Microservices in depth: discovery, resilience and observability | K11: Add-on days | L11: Resilience
A12: Pre-course | B12: Modern Java for Spring developers (pre-course bridge) | C12: Closes the gap for developers coming from Java 8 or another language, so Day 1 starts on Spring, not on syntax. | D12: Nothing. Recommended for developers coming from Java 8 or from another language. | E12: No | H12: =$E$14 | I12: =I11+IF(H12="Yes",1,0) | J12: Add-on 2 · Integrations: Razorpay payments, Resend e-mail and batch feeds | K12: Add-on days | L12: Integrations
A13: Add-on 1 | B13: Microservices in depth: discovery, resilience and observability | C13: Service discovery in depth, then timeouts, retries, circuit breakers and graceful degradation, and one checkout followed across five services with metrics, traces and logs. | D13: Core Day 4. | E13: No | H13: =$E$15 | I13: =I12+IF(H13="Yes",1,0) | J13: Add-on 3 · The Next.js storefront, part 1: foundations, catalogue and search | K13: Add-on days | L13: Storefront 1
A14: Add-on 2 | B14: Integrations: Razorpay payments, Resend e-mail and batch feeds | C14: Real providers in test mode: Razorpay with signature verification and webhooks, Resend behind a mail port with an outbox, a shipping partner behind WireMock, and Spring Batch for supplier and price feeds. | D14: Core Day 5. The Microservices in depth day is recommended first. | E14: No | H14: =$E$16 | I14: =I13+IF(H14="Yes",1,0) | J14: Add-on 4 · The Next.js storefront, part 2: cart, accounts and checkout | K14: Add-on days | L14: Storefront 2
A15: Add-on 3 | B15: The Next.js storefront, part 1: foundations, catalogue and search | C15: Build the ShopScope storefront from scratch with Next.js 16: App Router, locale routing, the BFF proxy, the region menu, then the product listing, product page and search against the real backend. | D15: Nothing from the core: the finished backend is provided as containers. Written for front-end developers; back-end developers are welcome. | E15: No | H15: =$E$17 | I15: =I14+IF(H15="Yes",1,0) | J15: Add-on 5 · Testing, part 1: unit tests, Spring slices and integration tests | K15: Add-on days | L15: Testing 1
A16: Add-on 4 | B16: The Next.js storefront, part 2: cart, accounts and checkout | C16: The cart and wishlist with optimistic updates, accounts with an httpOnly session and the cart-merge dialog, the checkout wizard with Razorpay Checkout.js, the confirmation page and order history, then production hardening. | D16: Storefront part 1. | E16: No | H16: =$E$18 | I16: =I15+IF(H16="Yes",1,0) | J16: Add-on 6 · Testing, part 2: between services, end to end and non-functional | K16: Add-on days | L16: Testing 2
A17: Add-on 5 | B17: Testing, part 1: unit tests, Spring slices and integration tests | C17: Unit tests that pay for themselves (JUnit 5 in depth, AssertJ, Mockito, property-based and mutation testing, ArchUnit), then Spring slices and integration tests with Testcontainers on PostgreSQL, MySQL and MongoDB. | D17: Core Day 3. | E17: No | H17: =$E$19 | I17: =I16+IF(H17="Yes",1,0) | J17: Add-on 7 · Docker: containerising the services and the storefront | K17: Add-on days | L17: Docker
A18: Add-on 6 | B18: Testing, part 2: between services, end to end and non-functional | C18: Consumer-driven contracts between services, partners and webhooks behind WireMock, Keycloak and Redis in Testcontainers, resilience under test, Playwright on the storefront, load tests with k6, and the quality gate. | D18: Testing part 1. The storefront days are recommended for the Playwright session. | E18: No | H18: =$E$20 | I18: =I17+IF(H18="Yes",1,0) | J18: Add-on 8 · Docker Compose: the whole system in one file | K18: Add-on days | L18: Compose
A19: Add-on 7 | B19: Docker: containerising the services and the storefront | C19: Small, safe images for every Spring Boot service and the Next.js storefront: multi-stage builds, layered jars, the JVM in a container, hardening and scanning, buildpacks and Jib, then the whole system run by hand and pushed to a registry. | D19: Core Day 4. | E19: No | H19: =$E$21 | I19: =I18+IF(H19="Yes",1,0) | J19: Add-on 9 · GitHub Actions: CI/CD for the whole system | K19: Add-on days | L19: GitHub Actions
A20: Add-on 8 | B20: Docker Compose: the whole system in one file | C20: One Compose file for services, storefront, PostgreSQL, MySQL, MongoDB, Redis, Keycloak and Mailpit, with health-checked start-up order, secrets, profiles, a fast inner loop and production-like runs. | D20: The Docker day. | E20: No | H20: =$E$22 | I20: =I19+IF(H20="Yes",1,0) | J20: Add-on 10 · Event-driven microservices with Kafka | K20: Add-on days | L20: Kafka & events
A21: Add-on 9 | B21: GitHub Actions: CI/CD for the whole system | C21: CI for a multi-service repository with caches, a matrix, path filters, Testcontainers and Playwright in CI, reusable workflows and a quality gate; then images to GHCR, OIDC to the cloud, gated environments, releases and a signed supply chain. | D21: The Docker day. | E21: No | H21: =$E$23 | I21: =I20+IF(H21="Yes",1,0) | J21: Add-on 11 · Kubernetes: ShopScope on a cluster | K21: Add-on days | L21: Kubernetes
A22: Add-on 10 | B22: Event-driven microservices with Kafka | C22: Decouple services with events: Kafka, reliable consumers with retries and dead-letter topics, the outbox done properly with Debezium, a search read model, and the checkout saga across order, inventory and payment. | D22: Core Day 5. The Integrations day is recommended first. | E22: No | H22: =$E$24 | I22: =I21+IF(H22="Yes",1,0) | J22: Add-on 12 · AI-enabled services with Spring AI | K22: Add-on days | L22: Spring AI
A23: Add-on 11 | B23: Kubernetes: ShopScope on a cluster | C23: Pods, Deployments, Services, configuration and secrets, probes, autoscaling and rolling updates, Helm charts for the system, and GitOps with Argo CD fed by the GitHub Actions pipeline. | D23: The Docker and Docker Compose days. GitHub Actions is recommended first. | E23: No | H23: =$E$25 | I23: =I22+IF(H23="Yes",1,0) | J23: Add-on 13 · Production readiness, migration and capstone | K23: Add-on days | L23: Capstone
A24: Add-on 12 | B24: AI-enabled services with Spring AI | C24: A shopping assistant on the real system: ChatClient, structured output and chat memory, RAG over the catalogue with pgvector, tool calling through the secured API, guardrails and evaluation, an MCP server and the storefront widget. | D24: Core Day 4. Ollama locally, or an API key for a hosted model. | E24: No
A25: Add-on 13 | B25: Production readiness, migration and capstone | C25: A production checklist, upgrading legacy Spring code to Boot 4 with OpenRewrite, and a capstone service built and reviewed end to end. | D25: Core Days 1–5. Best taken last. | E25: No
A27: Total | B27: =5+COUNTIF(E12:E25,"Yes")&" training days"
B28: =IF(AND($E$16="Yes",$E$15<>"Yes"),"Storefront part 2 needs Storefront part 1 first.","")
B29: =IF(AND($E$18="Yes",$E$17<>"Yes"),"Testing part 2 needs Testing part 1 first.","")
B30: =IF(AND($E$20="Yes",$E$19<>"Yes"),"Docker Compose needs the Docker day first.","")
B31: =IF(AND($E$21="Yes",$E$19<>"Yes"),"GitHub Actions needs the Docker day first.","")
B32: =IF(AND($E$23="Yes",$E$20<>"Yes"),"Kubernetes needs the Docker and Docker Compose days first.","")
A34: Your programme, day by day
A35: Day | B35: Title | C35: Details on sheet
A36: =IF(ISNA(MATCH(1,$I$5:$I$23,0)),"","Day 1") | B36: =IFERROR(INDEX($J$5:$J$23,MATCH(1,$I$5:$I$23,0)),"") | C36: =IFERROR(INDEX($K$5:$K$23,MATCH(1,$I$5:$I$23,0)),"") | L36: =IFERROR(INDEX($L$5:$L$23,MATCH(1,$I$5:$I$23,0)),"")
A37: =IF(ISNA(MATCH(2,$I$5:$I$23,0)),"","Day 2") | B37: =IFERROR(INDEX($J$5:$J$23,MATCH(2,$I$5:$I$23,0)),"") | C37: =IFERROR(INDEX($K$5:$K$23,MATCH(2,$I$5:$I$23,0)),"") | L37: =IFERROR(INDEX($L$5:$L$23,MATCH(2,$I$5:$I$23,0)),"")
A38: =IF(ISNA(MATCH(3,$I$5:$I$23,0)),"","Day 3") | B38: =IFERROR(INDEX($J$5:$J$23,MATCH(3,$I$5:$I$23,0)),"") | C38: =IFERROR(INDEX($K$5:$K$23,MATCH(3,$I$5:$I$23,0)),"") | L38: =IFERROR(INDEX($L$5:$L$23,MATCH(3,$I$5:$I$23,0)),"")
A39: =IF(ISNA(MATCH(4,$I$5:$I$23,0)),"","Day 4") | B39: =IFERROR(INDEX($J$5:$J$23,MATCH(4,$I$5:$I$23,0)),"") | C39: =IFERROR(INDEX($K$5:$K$23,MATCH(4,$I$5:$I$23,0)),"") | L39: =IFERROR(INDEX($L$5:$L$23,MATCH(4,$I$5:$I$23,0)),"")
A40: =IF(ISNA(MATCH(5,$I$5:$I$23,0)),"","Day 5") | B40: =IFERROR(INDEX($J$5:$J$23,MATCH(5,$I$5:$I$23,0)),"") | C40: =IFERROR(INDEX($K$5:$K$23,MATCH(5,$I$5:$I$23,0)),"") | L40: =IFERROR(INDEX($L$5:$L$23,MATCH(5,$I$5:$I$23,0)),"")
A41: =IF(ISNA(MATCH(6,$I$5:$I$23,0)),"","Day 6") | B41: =IFERROR(INDEX($J$5:$J$23,MATCH(6,$I$5:$I$23,0)),"") | C41: =IFERROR(INDEX($K$5:$K$23,MATCH(6,$I$5:$I$23,0)),"") | L41: =IFERROR(INDEX($L$5:$L$23,MATCH(6,$I$5:$I$23,0)),"")
A42: =IF(ISNA(MATCH(7,$I$5:$I$23,0)),"","Day 7") | B42: =IFERROR(INDEX($J$5:$J$23,MATCH(7,$I$5:$I$23,0)),"") | C42: =IFERROR(INDEX($K$5:$K$23,MATCH(7,$I$5:$I$23,0)),"") | L42: =IFERROR(INDEX($L$5:$L$23,MATCH(7,$I$5:$I$23,0)),"")
A43: =IF(ISNA(MATCH(8,$I$5:$I$23,0)),"","Day 8") | B43: =IFERROR(INDEX($J$5:$J$23,MATCH(8,$I$5:$I$23,0)),"") | C43: =IFERROR(INDEX($K$5:$K$23,MATCH(8,$I$5:$I$23,0)),"") | L43: =IFERROR(INDEX($L$5:$L$23,MATCH(8,$I$5:$I$23,0)),"")
...

Sheet 5-day core
A1: ShopScope Commerce: Spring Boot and Microservices · the 5-day core
A2: Five days every team takes: a plain-Java monolith and its problem register, Spring Core taking over the wiring, Spring Boot with a REST API and PostgreSQL, relationships, search and transactions, then the monolith split into microservices on PostgreSQL, MySQL and MongoDB behind a gateway, and security with JWT and Keycloak. Breaks are on each day sheet; this page shows the sessions only.
A4: Session | B4: Start | C4: End | D4: Session title | E4: Demo | F4: Topics covered | G4: Labs covered
A5: Day 1 — From a plain-Java monolith to Spring Core
A6: ='Core Day 1'!A6 | B6: ='Core Day 1'!B6 | C6: ='Core Day 1'!C6 | D6: ='Core Day 1'!D6 | E6: ='Core Day 1'!E6 | F6: ='Core Day 1'!F6 | G6: ='Core Day 1'!G6
A7: ='Core Day 1'!A8 | B7: ='Core Day 1'!B8 | C7: ='Core Day 1'!C8 | D7: ='Core Day 1'!D8 | E7: ='Core Day 1'!E8 | F7: ='Core Day 1'!F8 | G7: ='Core Day 1'!G8
A8: ='Core Day 1'!A10 | B8: ='Core Day 1'!B10 | C8: ='Core Day 1'!C10 | D8: ='Core Day 1'!D10 | E8: ='Core Day 1'!E10 | F8: ='Core Day 1'!F10 | G8: ='Core Day 1'!G10
A9: ='Core Day 1'!A12 | B9: ='Core Day 1'!B12 | C9: ='Core Day 1'!C12 | D9: ='Core Day 1'!D12 | E9: ='Core Day 1'!E12 | F9: ='Core Day 1'!F12 | G9: ='Core Day 1'!G12
A11: Day 2 — Spring Boot, a REST API and PostgreSQL
A12: ='Core Day 2'!A6 | B12: ='Core Day 2'!B6 | C12: ='Core Day 2'!C6 | D12: ='Core Day 2'!D6 | E12: ='Core Day 2'!E6 | F12: ='Core Day 2'!F6 | G12: ='Core Day 2'!G6
A13: ='Core Day 2'!A8 | B13: ='Core Day 2'!B8 | C13: ='Core Day 2'!C8 | D13: ='Core Day 2'!D8 | E13: ='Core Day 2'!E8 | F13: ='Core Day 2'!F8 | G13: ='Core Day 2'!G8
A14: ='Core Day 2'!A10 | B14: ='Core Day 2'!B10 | C14: ='Core Day 2'!C10 | D14: ='Core Day 2'!D10 | E14: ='Core Day 2'!E10 | F14: ='Core Day 2'!F10 | G14: ='Core Day 2'!G10
A15: ='Core Day 2'!A12 | B15: ='Core Day 2'!B12 | C15: ='Core Day 2'!C12 | D15: ='Core Day 2'!D12 | E15: ='Core Day 2'!E12 | F15: ='Core Day 2'!F12 | G15: ='Core Day 2'!G12
A17: Day 3 — Relationships, search, transactions and the safety net
A18: ='Core Day 3'!A6 | B18: ='Core Day 3'!B6 | C18: ='Core Day 3'!C6 | D18: ='Core Day 3'!D6 | E18: ='Core Day 3'!E6 | F18: ='Core Day 3'!F6 | G18: ='Core Day 3'!G6
A19: ='Core Day 3'!A8 | B19: ='Core Day 3'!B8 | C19: ='Core Day 3'!C8 | D19: ='Core Day 3'!D8 | E19: ='Core Day 3'!E8 | F19: ='Core Day 3'!F8 | G19: ='Core Day 3'!G8
A20: ='Core Day 3'!A10 | B20: ='Core Day 3'!B10 | C20: ='Core Day 3'!C10 | D20: ='Core Day 3'!D10 | E20: ='Core Day 3'!E10 | F20: ='Core Day 3'!F10 | G20: ='Core Day 3'!G10
A21: ='Core Day 3'!A12 | B21: ='Core Day 3'!B12 | C21: ='Core Day 3'!C12 | D21: ='Core Day 3'!D12 | E21: ='Core Day 3'!E12 | F21: ='Core Day 3'!F12 | G21: ='Core Day 3'!G12
A23: Day 4 — From monolith to microservices
A24: ='Core Day 4'!A6 | B24: ='Core Day 4'!B6 | C24: ='Core Day 4'!C6 | D24: ='Core Day 4'!D6 | E24: ='Core Day 4'!E6 | F24: ='Core Day 4'!F6 | G24: ='Core Day 4'!G6
A25: ='Core Day 4'!A8 | B25: ='Core Day 4'!B8 | C25: ='Core Day 4'!C8 | D25: ='Core Day 4'!D8 | E25: ='Core Day 4'!E8 | F25: ='Core Day 4'!F8 | G25: ='Core Day 4'!G8
A26: ='Core Day 4'!A10 | B26: ='Core Day 4'!B10 | C26: ='Core Day 4'!C10 | D26: ='Core Day 4'!D10 | E26: ='Core Day 4'!E10 | F26: ='Core Day 4'!F10 | G26: ='Core Day 4'!G10
A27: ='Core Day 4'!A12 | B27: ='Core Day 4'!B12 | C27: ='Core Day 4'!C12 | D27: ='Core Day 4'!D12 | E27: ='Core Day 4'!E12 | F27: ='Core Day 4'!F12 | G27: ='Core Day 4'!G12
A29: Day 5 — Security: Spring Security, JWT, securing the system, and Keycloak
A30: ='Core Day 5'!A6 | B30: ='Core Day 5'!B6 | C30: ='Core Day 5'!C6 | D30: ='Core Day 5'!D6 | E30: ='Core Day 5'!E6 | F30: ='Core Day 5'!F6 | G30: ='Core Day 5'!G6
A31: ='Core Day 5'!A8 | B31: ='Core Day 5'!B8 | C31: ='Core Day 5'!C8 | D31: ='Core Day 5'!D8 | E31: ='Core Day 5'!E8 | F31: ='Core Day 5'!F8 | G31: ='Core Day 5'!G8
A32: ='Core Day 5'!A10 | B32: ='Core Day 5'!B10 | C32: ='Core Day 5'!C10 | D32: ='Core Day 5'!D10 | E32: ='Core Day 5'!E10 | F32: ='Core Day 5'!F10 | G32: ='Core Day 5'!G10
A33: ='Core Day 5'!A12 | B33: ='Core Day 5'!B12 | C33: ='Core Day 5'!C12 | D33: ='Core Day 5'!D12 | E33: ='Core Day 5'!E12 | F33: ='Core Day 5'!F12 | G33: ='Core Day 5'!G12

Sheet Core Day 1
A1: Day 1 — From a plain-Java monolith to Spring Core
A2: ShopScope Commerce, the online store built across the whole programme, starts as a plain-Java monolith: the whole backend in one process, wired by hand, with a written register of its problems. Then Spring takes over the wiring, and configuration, events and aspects move out of the business code.
A3: Demo 1's code is pre-built; its labs read, run, break and measure it. Lab 7 (the testing context) of Demo 3 is demonstrated rather than typed.
A5: Session | B5: Start | C5: End | D5: Session title | E5: Demo | F5: Topics covered | G5: Labs covered
A6: S1 | B6: ='Settings and notes'!$C$4 | C6: =B6+TIME(1,10,0) | D6: ShopScope as a plain-Java monolith | E6: Demo 1 | F6: The whole backend in miniature, with no framework: seven modules behind the same /api contract the microservices will later serve, in-memory stores, a composition root made of "new", a hand-written properties loader, logging pasted into every method and a hand-rolled HTTP layer. It works. The session is about seeing why it will not keep working: the dependency arrows that should not exist, the untestable OrderService with its hidden gateway, the overselling bug when a payment fails after stock was decremented, and the problem register every later demo closes one line at a time. | G6: Lab 1 Tour: the seven modules and the arrows that should not exist (10) Lab 2 The composition root: add one dependency and count the files you touch (15) Lab 3 Try to unit-test OrderService (10) Lab 4 The shared in-memory store and the overselling bug (15) Lab 5 The problem register (10)
A7: Break | B7: =C6 | C7: =B7+'Settings and notes'!$C$5/1440
A8: S2 | B8: =C7 | C8: =B8+TIME(1,30,0) | D8: The container takes over the wiring | E8: Demo 2 (part 1) | F8: The composition root of Demo 1 becomes the container's job. Dependency injection by hand, then with the container: ApplicationContext, @Configuration and @Bean. Every way to define a bean: @Component and stereotypes with scanning, @Bean and @Import, XML (read it, for legacy code), FactoryBean and programmatic registration. Injection: constructor vs setter vs field, optional dependencies, @Primary and @Qualifier, a custom qualifier, injecting a List or Map (the discount-rule chain), ObjectProvider and @Lazy. OrderService becomes testable. | G8: Lab 1 The wiring problem, and dependency injection by hand (15) Lab 2 The container: @Configuration and @Bean (20) Lab 3 Every way to define a bean (25) Lab 4 Injection: constructor, qualifiers, List and Map (25)
A9: Lunch | B9: =C8 | C9: =B9+'Settings and notes'!$C$6/1440
A10: S3 | B10: =C9 | C10: =B10+TIME(1,20,0) | D10: Scopes, the bean lifecycle and post-processors | E10: Demo 2 (part 2) | F10: Singleton vs prototype and the stateful-singleton bug; a prototype inside a singleton. The bean lifecycle traced end to end: instantiation, population, Aware interfaces, BeanPostProcessor before and after (where proxies appear), @PostConstruct, afterPropertiesSet, init methods, @PreDestroy and SmartLifecycle. BeanFactoryPostProcessor vs BeanPostProcessor, bean definition overriding, and circular dependencies. | G10: Lab 5 Scopes and the stateful singleton (15) Lab 6 The lifecycle, traced end to end (25) Lab 7 A BeanFactoryPostProcessor and a BeanPostProcessor (15) Lab 8 Overriding and circular dependencies (10)
A11: Break | B11: =C10 | C11: =B11+'Settings and notes'!$C$5/1440
A12: S4 | B12: =C11 | C12: =B12+TIME(1,35,0) | D12: Configuration, events and aspects move out of the business code | E12: Demo 3 | F12: Environment, @PropertySource, @Value and SpEL replace the hand-written properties loader. Profiles: tax rules per region (India, UK, US). @Conditional with a custom condition. Application events: OrderPlaced reaches the notification module without a direct call; @EventListener, ordering and async listeners. AOP: a proxy by hand, JDK vs CGLIB, @Aspect, pointcuts and @Around; the pasted timing and audit code becomes one @Audited aspect; and the self-invocation trap that explains why @Transactional and @Cacheable sometimes do nothing. | G12: Lab 1 Environment, @Value and SpEL replace the properties loader (15) Lab 2 Profiles: tax rules per region (15) Lab 3 A custom @Conditional (10) Lab 4 Application events: OrderPlaced (15) Lab 5 AOP: proxies, aspects and @Audited (25) Lab 6 The self-invocation trap (5)

Sheet Core Day 2
A1: Day 2 — Spring Boot, a REST API and PostgreSQL
A2: The monolith becomes a Spring Boot application with a starter of its own. Its hand-rolled HTTP layer becomes a REST API the storefront can rely on (stores and regions first, then products), with one error contract and live documentation, and the catalogue leaves memory for PostgreSQL with versioned migrations and localised data.
A3: API versioning, ETags and the structured-logging lab are demonstrated rather than typed; their code is in the finished demo.
A5: Session | B5: Start | C5: End | D5: Session title | E5: Demo | F5: Topics covered | G5: Labs covered
A6: S1 | B6: ='Settings and notes'!$C$4 | C6: =B6+TIME(1,30,0) | D6: The monolith becomes a Spring Boot application | E6: Demo 4 | F6: Adding Boot to the same project: the parent, starters, @SpringBootApplication taken apart. Auto-configuration: delete what Boot now provides, read the conditions report, override with @ConditionalOnMissingBean. Externalised configuration: application.yml, property-source order, profiles, @ConfigurationProperties records with validation. Our own auto-configuration in libs/shopscope-starter (request ids, a clock, the shopper session). ApplicationRunner, Actuator and the executable jar. | G6: Lab 1 Add Boot: parent, starters, @SpringBootApplication (20) Lab 2 Auto-configuration and the conditions report (20) Lab 3 Externalised configuration (15) Lab 4 Write our own starter (20) Lab 5 Actuator and the executable jar (10)
A7: Break | B7: =C6 | C7: =B7+'Settings and notes'!$C$5/1440
A8: S2 | B8: =C7 | C8: =B8+TIME(1,35,0) | D8: The hand-rolled HTTP layer becomes a REST API | E8: Demo 5 | F8: A multi-module build: a parent POM and one Maven module per bounded context, with the dependency rules the modules may not break. Spring MVC under REST: DispatcherServlet, handler mapping, message converters. Resource design: URIs, methods, idempotency, status codes, and the /api contract we keep. Stores and the store context (country, language, currency) as the first resource, then product CRUD with ResponseEntity, Location headers, 204 and 404 replacing the HttpServer handlers. View records, MapStruct and hand-written mappers, Jackson 3, and .http request files. | G8: Lab 1 One Maven module per bounded context (15) Lab 2 Spring MVC under REST, and resource design (15) Lab 3 Stores and the store context (20) Lab 4 Product CRUD replaces the HttpServer handlers (25) Lab 5 View records and MapStruct (15)
A9: Lunch | B9: =C8 | C9: =B9+'Settings and notes'!$C$6/1440
A10: S3 | B10: =C9 | C10: =B10+TIME(1,25,0) | D10: One error contract, and an API people can read | E10: Demo 6 | F10: Bean Validation on requests, groups and a custom constraint (@ValidSku). One error contract: ProblemDetail (RFC 9457) from @RestControllerAdvice, moved into the shared starter so every module, and later every service, answers the same way. Paging, sorting and filtering in the contract. API versioning with Spring Framework 7, OpenAPI 3 with springdoc and Swagger UI, and conditional requests with ETags. | G10: Lab 1 Bean Validation and a custom constraint (20) Lab 2 One error contract with ProblemDetail (25) Lab 3 Paging, sorting and filtering (15) Lab 4 OpenAPI and Swagger UI (15)
A11: Break | B11: =C10 | C11: =B11+'Settings and notes'!$C$5/1440
A12: S4 | B12: =C11 | C12: =B12+TIME(1,30,0) | D12: The catalogue leaves memory: Spring Data JPA on PostgreSQL | E12: Demo 7 | F12: JPA, Hibernate and Spring Data: who does what, and the infrastructure boundary that keeps JPA types out of the domain. The first @Entity. Flyway migrations and seed data, and why ddl-auto stays off. Localised names, descriptions and slugs per locale with fallback and slug routing. JpaRepository, derived queries, @Query (JPQL and native), paging, sorting and projections. Custom attributes as JSONB, and seeing the SQL. | G12: Lab 1 The first entity, and the boundary (20) Lab 2 Flyway migrations and seed data (15) Lab 3 Localised data and slug routing (20) Lab 4 Repositories, derived queries and @Query (15) Lab 5 Paging, projections and JSONB attributes (15)

Sheet Core Day 3
A1: Day 3 — Relationships, search, transactions and the safety net
A2: The catalogue model gets relationships that perform, full-text search, facets and a composed product-listing endpoint. The order module moves to the database with carts, checkout and transactions that behave under concurrent load, and the overselling bug from Day 1 is fixed. The day closes with the minimum test suite every module keeps from here on.
A3: JPA auditing and soft delete are demonstrated rather than typed. Testing is covered in depth in the two Testing add-on days; Demo 11 is the safety net the core needs.
A5: Session | B5: Start | C5: End | D5: Session title | E5: Demo | F5: Topics covered | G5: Labs covered
A6: S1 | B6: ='Settings and notes'!$C$4 | C6: =B6+TIME(1,20,0) | D6: Relationships that perform | E6: Demo 8 | F6: Category tree, product, variants, images, reviews and store-to-product: @ManyToOne, @OneToMany, @ManyToMany and the owning side. The variant matrix and bundles (a product composed of products), cascades, orphanRemoval, equals and hashCode. The N+1 problem caught on the product list and fixed three ways: JOIN FETCH, @EntityGraph and DTO projections. Batch fetching, open-in-view off, LazyInitializationException explained, auditing and soft delete. | G6: Lab 1 The catalogue model and the owning side (25) Lab 2 Variants, bundles and cascades (15) Lab 3 Catch the N+1 (10) Lab 4 Fix it three ways (20)
A7: Break | B7: =C6 | C7: =B7+'Settings and notes'!$C$5/1440
A8: S2 | B8: =C7 | C8: =B8+TIME(1,25,0) | D8: Search, facets and the product listing | E8: Demo 9 | F8: Filters from the API to SQL with Specifications; store-scoped and category-subtree queries. Full-text search with tsvector, ranking and a generated column. Facets: counts per attribute, price ranges and post-filtering semantics. One composed /api/plp response (cards, facets, total, sort) and its caching. When PostgreSQL is not enough: OpenSearch as a read model, previewed. | G8: Lab 1 Specifications, store scope and category subtrees (20) Lab 2 Full-text search with tsvector (20) Lab 3 Facets and post-filtering (20) Lab 4 The composed product-listing endpoint (15)
A9: Lunch | B9: =C8 | C9: =B9+'Settings and notes'!$C$6/1440
A10: S3 | B10: =C9 | C10: =B10+TIME(1,40,0) | D10: Carts, checkout and the overselling bug, fixed | E10: Demo 10 | F10: The order module moves to PostgreSQL: cart and order aggregates on JPA, line items, a bundle as one unit, a Subscribe & Save line. The cart write model: quantities, shipping address, pickup vs delivery, shipping methods, discount codes, the summary. Cart rules as a rule chain with the List injection from Day 1. @Transactional at the service layer: what the proxy does, readOnly, rollback rules, propagation and isolation demonstrated; the Demo 1 overselling scenario replayed, and fixed. Two tabs, one cart: optimistic locking with @Version and a retry; pessimistic locking, and when. Checkout: the order number and idempotency key, and @TransactionalEventListener for "order placed". | G10: Lab 1 Cart and order aggregates on JPA (20) Lab 2 The cart write model and cart rules (20) Lab 3 @Transactional, propagation and isolation: the overselling bug, fixed (25) Lab 4 Two tabs, one cart: optimistic and pessimistic locking (15) Lab 5 Checkout, idempotency and transactional events (10)
A11: Break | B11: =C10 | C11: =B11+'Settings and notes'!$C$5/1440
A12: S4 | B12: =C11 | C12: =B12+TIME(1,20,0) | D12: The safety net: tests every module keeps | E12: Demo 11 | F12: The test pyramid for a service and what belongs where. Unit tests with JUnit, Mockito and AssertJ, and test-data builders for carts and products. @WebMvcTest with MockMvcTester for a controller and the error contract. @DataJpaTest with Testcontainers and @ServiceConnection against a real PostgreSQL, and context caching so the suite stays fast. | G12: Lab 1 The pyramid for a service (10) Lab 2 Unit tests and test-data builders (20) Lab 3 Controller tests with @WebMvcTest (20) Lab 4 Repository tests with Testcontainers (20)

Sheet Core Day 4
A1: Day 4 — From monolith to microservices
A2: The modular monolith is split. The catalogue becomes the first service, extracted by hand with every consequence felt; the remaining modules follow as pre-built services, with orders on MySQL and customers on MongoDB, and a checkout that now spans four services. Configuration is centralised, services find each other, and one gateway exposes the /api contract. At the end of the day the Next.js storefront runs against the real system.
A3: The extracted services of Demo 13 arrive pre-built, so the session stays on what is new: MySQL, MongoDB and the checkout across four services. Demos 14 and 15 share one session: config refresh in depth, OpenFeign and registry internals move to the Microservices in depth add-on.
A5: Session | B5: Start | C5: End | D5: Session title | E5: Demo | F5: Topics covered | G5: Labs covered
A6: S1 | B6: ='Settings and notes'!$C$4 | C6: =B6+TIME(1,35,0) | D6: The first cut: the catalogue becomes a service | E6: Demo 12 | F6: Monolith vs modular monolith vs microservices; bounded contexts; database per service; the strangler pattern; the ShopScope target map. The catalog module becomes catalog-service with its own PostgreSQL database and the /api/products routes. The monolith calls it with RestClient (a product snapshot at checkout), then through an @HttpExchange interface. Timeouts, connection pools, a downstream ProblemDetail mapped to our own, correlation ids across processes, and running several processes locally. | G6: Lab 1 Architecture, not code (15) Lab 2 Extract catalog-service (25) Lab 3 RestClient, then an HTTP interface (20) Lab 4 Timeouts and error mapping (15) Lab 5 Correlation ids across processes (10)
A7: Break | B7: =C6 | C7: =B7+'Settings and notes'!$C$5/1440
A8: S2 | B8: =C7 | C8: =B8+TIME(1,40,0) | D8: The monolith is gone: pricing, inventory, orders on MySQL, customers on MongoDB | E8: Demo 13 | F8: The remaining modules extracted the same way, pre-built. pricing-service and inventory-service on PostgreSQL: the scoped price on every card and line, stock per supply channel, availability badges, the stock gate, reservations. order-service on MySQL: the same Spring Data JPA, a different dialect, Flyway for MySQL, and the Day 3 locking test re-run on InnoDB (REPEATABLE READ vs READ COMMITTED). customer-service on MongoDB: why a customer is a document with an embedded address book, Spring Data MongoDB, @Document, MongoRepository and MongoTemplate, indexes, schema evolution without migrations, @DataMongoTest with Testcontainers. Checkout across four services, and what happens when step three fails. | G8: Lab 1 Pricing and inventory as services (15) Lab 2 order-service on MySQL: dialect, Flyway, InnoDB locking (25) Lab 3 customer-service on MongoDB (30) Lab 4 Checkout across four services, and the failure (20)
A9: Lunch | B9: =C8 | C9: =B9+'Settings and notes'!$C$6/1440
A10: S3 | B10: =C9 | C10: =B10+TIME(1,25,0) | D10: Every service reads its configuration from one place, and services find each other | E10: Demos 14–15 | F10: Spring Cloud Config Server backed by a Git repository: one file per service per profile, spring.config.import, fail-fast and retry, encrypted secrets and provider keys that never enter Git, @RefreshScope and feature flags. A Eureka discovery server, registrations, and client-side load balancing with a @LoadBalanced RestClient across two instances. | G10: Lab 1 Config Server from Git (20) Lab 2 The client side, and secrets (15) Lab 3 Refresh at runtime and feature flags (15) Lab 4 Eureka and a load-balanced RestClient (25)
A11: Break | B11: =C10 | C11: =B11+'Settings and notes'!$C$5/1440
A12: S4 | B12: =C11 | C12: =B12+TIME(1,25,0) | D12: One front door: the API gateway, and the storefront arrives | E12: Demo 16 | F12: Spring Cloud Gateway: the /api contract as routes, predicates and lb:// URIs. Filters: path rewriting, request ids, the shopper-session cookie, a custom global filter. CORS once at the edge, rate limiting with Redis, and one OpenAPI page aggregated for every service. The finished Next.js storefront runs against the gateway and browses the real catalogue. The problem register of Day 1 is empty. | G12: Lab 1 Routes through the gateway (25) Lab 2 Filters and the shopper session (20) Lab 3 CORS and rate limiting (15) Lab 4 The storefront arrives (15)

Sheet Core Day 5
A1: Day 5 — Security: Spring Security, JWT, securing the system, and Keycloak
A2: From the security filter chain to an identity service that issues JWTs, resource servers that validate them, the guest-to-customer session boundary, ownership rules, service-to-service credentials, and finally handing login over to Keycloak with OAuth2 and OpenID Connect.
A3: Method security on the back-office endpoints and the OWASP API Security Top 10 review are demonstrated rather than typed.
A5: Session | B5: Start | C5: End | D5: Session title | E5: Demo | F5: Topics covered | G5: Labs covered
A6: S1 | B6: ='Settings and notes'!$C$4 | C6: =B6+TIME(1,25,0) | D6: Who are you? The identity service and Spring Security fundamentals | E6: Demo 17 | F6: The filter chain on every request and what the default does. SecurityFilterChain as a bean; authentication vs authorisation. Users in PostgreSQL with UserDetailsService, BCrypt and DelegatingPasswordEncoder. Registration, e-mail uniqueness, password rules, the password-reset token and the e-mail-verification token. CSRF (when it matters, when a stateless API turns it off), CORS and security headers. | G6: Lab 1 What the default does (10) Lab 2 Your own SecurityFilterChain (15) Lab 3 Users in the database (25) Lab 4 Registration, reset and verification tokens (20) Lab 5 CSRF, CORS and headers (10)
A7: Break | B7: =C6 | C7: =B7+'Settings and notes'!$C$5/1440
A8: S2 | B8: =C7 | C8: =B8+TIME(1,40,0) | D8: Tokens everywhere: JWT, resource servers and the session boundary | E8: Demo 18 | F8: A JWT decoded: header, claims, signature; HMAC vs RSA. Login that issues an RS256 token with JwtEncoder and a JWKS endpoint. The other services as OAuth2 resource servers validating via the JWKS URI. Roles and scopes from claims to authorities. Refresh tokens with rotation and reuse detection, stored hashed. The session boundary: the anonymous cart merged into the customer's cart on login, with a merge mode, and sign-out. Logout, revocation and the bad-token checklist. | G8: Lab 1 Decode a JWT (10) Lab 2 A login that issues RS256 tokens, and JWKS (25) Lab 3 Services as resource servers (20) Lab 4 Roles from claims (10) Lab 5 Refresh tokens with rotation (15) Lab 6 Guest to customer: the cart merge (15)
A9: Lunch | B9: =C8 | C9: =B9+'Settings and notes'!$C$6/1440
A10: S3 | B10: =C9 | C10: =B10+TIME(1,25,0) | D10: Securing the calls between services | E10: Demo 19 | F10: JWT validation at the gateway and token relay to services. Ownership: customers see only their own orders, addresses and shopping lists. Service-to-service calls with client credentials, and never forwarding a user token blindly. Security tests with @WithMockUser and the jwt() post-processor. The OWASP API Security Top 10 checked against ShopScope. | G10: Lab 1 JWT at the gateway, and token relay (25) Lab 2 Ownership: only your own orders (20) Lab 3 Client credentials between services (20) Lab 4 Security tests (15)
A11: Break | B11: =C10 | C11: =B11+'Settings and notes'!$C$5/1440
A12: S4 | B12: =C11 | C12: =B12+TIME(1,30,0) | D12: Login leaves the building: Keycloak, OAuth2 and OpenID Connect | E12: Demo 20 | F12: Why teams stop running their own login. OAuth2 roles and flows, and OIDC. Keycloak in a container: realm, clients and roles imported from JSON. Swap the issuer: the services trust Keycloak and the identity service retires. The storefront signs in with authorization code + PKCE through the gateway as a backend-for-frontend (oauth2Login, TokenRelay, an httpOnly cookie), compared with a public SPA client. Client credentials for back-office jobs and mapping realm roles. | G12: Lab 1 OAuth2 flows and OIDC (10) Lab 2 Keycloak in a container (20) Lab 3 Swap the issuer (20) Lab 4 The storefront signs in with PKCE (25) Lab 5 Client credentials and realm roles (10)

Sheet Add-on days
A1: Add-on days · each one adds exactly one day
A2: Choose any add-ons on the "Build your programme" sheet. Each is a complete training day with the same rhythm as the core: two short breaks and a lunch.
A4: Pre-course · Modern Java for Spring developers (pre-course bridge)
A5: When | B5: Before Day 1
A6: Requires | B6: Nothing. Recommended for developers coming from Java 8 or from another language.
A7: Why add it | B7: Spring Boot 4 code is written in modern Java: records, sealed types, pattern matching, lambdas and streams appear in every demo. This day builds the plain-Java pricing domain that Day 1 wires into Spring, so nobody learns the language and the framework at the same time.
A8: Session | B8: Start | C8: End | D8: Session title | E8: Demo | F8: Topics covered | G8: Labs covered
A9: S1 | B9: ='Settings and notes'!$C$4 | C9: =B9+TIME(1,30,0) | D9: The modern Java language | E9: Demo 0 (part 1) | F9: Records, immutability and Money as a value object; var, text blocks and switch expressions; sealed interfaces and pattern matching for price rules and price-selection precedence; Optional, exceptions and the rules of a clean API. | G9: Lab 1 Records, immutability and Money (25) Lab 2 Sealed interfaces and pattern matching for price rules (25) Lab 3 Switch expressions, text blocks and var (15) Lab 4 Optional, exceptions and a clean API (15)
A10: Break | B10: =C9 | C10: =B10+'Settings and notes'!$C$5/1440
A11: S2 | B11: =C10 | C11: =B11+TIME(1,25,0) | D11: Lambdas, streams and collections | E11: Demo 0 (part 2) | F11: Functional interfaces and method references, the stream toolbox (map, filter, collect, groupingBy) over a basket, Optional used properly, immutable collections, and executors and futures (with the one line that becomes virtual threads on Java 21+). | G11: Lab 5 Lambdas and method references (20) Lab 6 Streams and collectors over a basket (30) Lab 7 Reports with groupingBy (15) Lab 8 Executors, futures and virtual threads (10)
A12: Lunch | B12: =C11 | C12: =B12+'Settings and notes'!$C$6/1440
A13: S3 | B13: =C12 | C13: =B13+TIME(1,25,0) | D13: Maven, JUnit 5 and the project | E13: Demo 0 (part 3) | F13: The Maven lifecycle, dependencies and BOMs, multi-module builds and the Maven wrapper. JUnit 5 and AssertJ basics, Mockito basics, and an IDE set up for Spring with the Day 1 starter. | G13: Lab 9 Maven: lifecycle, dependencies, the wrapper (25) Lab 10 JUnit 5 and AssertJ: the first tests (25) Lab 11 Mocks with Mockito (15) Lab 12 The Day 1 starter project (10)
A14: Break | B14: =C13 | C14: =B14+'Settings and notes'!$C$5/1440
A15: S4 | B15: =C14 | C15: =B15+TIME(1,20,0) | D15: SQL, JDBC and HTTP essentials | E15: Demo 0 (part 4) | F15: An SQL refresher (joins, indexes) on the ShopScope schema, plain JDBC once so the ORM makes sense on Day 2, a first look at a document in MongoDB, and HTTP essentials (methods, status codes, headers, JSON) with curl. | G15: Lab 13 SQL on the ShopScope schema (25) Lab 14 Plain JDBC, once (20) Lab 15 A document in MongoDB (10) Lab 16 HTTP with curl (15)
A17: Add-on 1 · Microservices in depth: discovery, resilience and observability
A18: When | B18: After the core
A19: Requires | B19: Core Day 4.
A20: Why add it | B20: For teams running microservices in production: failures are normal, and the patterns that contain them are learned on ShopScope's own services before they are applied to partners.
A21: Session | B21: Start | C21: End | D21: Session title | E21: Demo | F21: Topics covered | G21: Labs covered
A22: S1 | B22: ='Settings and notes'!$C$4 | C22: =B22+TIME(1,20,0) | D22: Service discovery in depth | E22: Demo 15 | F22: OpenFeign compared with HTTP interfaces, so you can read either. Health, heartbeats, self-preservation and what "down" means to a registry. Two instances behind client-side load balancing, and why Kubernetes makes Eureka optional. | G22: Lab 1 OpenFeign vs HTTP interfaces (20) Lab 2 Health, heartbeats and self-preservation (20) Lab 3 Two instances, load-balanced (20) Lab 4 Discovery vs platform DNS (10)
A23: Break | B23: =C22 | C23: =B23+'Settings and notes'!$C$5/1440
A24: S2 | B24: =C23 | C24: =B24+TIME(1,35,0) | D24: When inventory is slow: resilience patterns | E24: Demo 21 | F24: Latency and failures injected into the inventory service on purpose. Timeouts everywhere, and why they come first. Retries with backoff and jitter, and idempotency keys so a retried POST is safe. Circuit breaker and fallbacks with Resilience4j, bulkheads and rate limiters, and Spring Framework 7's built-in @Retryable and @ConcurrencyLimit compared. | G24: Lab 1 Break it on purpose (10) Lab 2 Timeouts first (15) Lab 3 Retries, backoff and idempotency keys (20) Lab 4 Circuit breaker and fallbacks (25) Lab 5 Bulkheads, rate limiters and @Retryable (15)
A25: Lunch | B25: =C24 | C25: =B25+'Settings and notes'!$C$6/1440
A26: S3 | B26: =C25 | C26: =B26+TIME(1,20,0) | D26: One checkout, seen across five services: health, metrics and alerts | E26: Demo 22 (part 1) | F26: Actuator health groups, liveness and readiness. Micrometer metrics to Prometheus and a Grafana dashboard per service. Business metrics: orders per minute, payment failures. Alerts and SLOs: what to page on, what to ignore. | G26: Lab 1 Health groups, liveness and readiness (15) Lab 2 Micrometer, Prometheus and Grafana (25) Lab 3 Business metrics (15) Lab 4 Alerts and SLOs (15)
A27: Break | B27: =C26 | C27: =B27+'Settings and notes'!$C$5/1440
A28: S4 | B28: =C27 | C28: =B28+TIME(1,15,0) | D28: Tracing, logs and graceful degradation | E28: Demo 22 (part 2) | F28: Distributed tracing with OpenTelemetry: one checkout followed across five services in Tempo. Structured logs to Loki with the trace id in every line. Graceful degradation: the product listing without stock badges, checkout readiness, and what the customer sees. | G28: Lab 5 One checkout across five services (30) Lab 6 Logs with the trace id (20) Lab 7 Graceful degradation in checkout (15)
A30: Add-on 2 · Integrations: Razorpay payments, Resend e-mail and batch feeds
A31: When | B31: After the core
A32: Requires | B32: Core Day 5. The Microservices in depth day is recommended first.
A33: Why add it | B33: This is the enterprise edge: money, e-mail and partners are the least reliable dependencies a system has, and the day shows how to integrate them without trusting them.
A34: Session | B34: Start | C34: End | D34: Session title | E34: Demo | F34: Topics covered | G34: Labs covered
A35: S1 | B35: ='Settings and notes'!$C$4 | C35: =B35+TIME(1,10,0) | D35: Taking the money: payments with Razorpay | E35: Demo 23 (part 1) | F35: The payment port and the Razorpay adapter: the checkout session creates a Razorpay Order (amount in paise, receipt = our order number). Idempotency keys on every money-moving call. Verifying the checkout result: the HMAC-SHA256 signature over order_id|payment_id. The ledger lives in MySQL. | G35: Lab 1 The payment port and the Razorpay adapter (25) Lab 2 Idempotency keys (15) Lab 3 Verifying the signature (20)
A36: Break | B36: =C35 | C36: =B36+'Settings and notes'!$C$5/1440
A37: S2 | B37: =C36 | C37: =B37+TIME(1,15,0) | D37: Webhooks, the ledger and order states | E37: Demo 23 (part 2) | F37: Webhooks in: X-Razorpay-Signature verification, replay protection and out-of-order delivery for payment.authorized, payment.captured, payment.failed and refund.processed, replayed locally from fixtures. The payment ledger, capture at fulfilment, refunds, and the guarded order state machine. WireMock as the Razorpay sandbox in tests. | G37: Lab 4 Webhooks: signatures, replays, ordering (30) Lab 5 The ledger, capture, refunds and order states (25) Lab 6 WireMock as the sandbox (10)
A38: Lunch | B38: =C37 | C38: =B38+'Settings and notes'!$C$6/1440
A39: S3 | B39: =C38 | C39: =B39+TIME(1,40,0) | D39: Telling the customer: Resend, and the outbox | E39: Demo 24 | F39: The notification service on MongoDB: templates and the delivery log as documents, Thymeleaf rendering, a MailSender port with two adapters, Resend (the Java SDK and its test addresses) and SMTP to Mailpit for offline runs. Asynchronous delivery with @Async and the transactional outbox. The order timeline: an append-only event log fed from the outbox and an idempotent consumer with a checkpoint. Resend delivery webhooks and e-mail verification end to end. | G39: Lab 1 The mail port, Resend and Mailpit (30) Lab 2 @Async and the transactional outbox (25) Lab 3 The order timeline and the idempotent consumer (20) Lab 4 Delivery webhooks and e-mail verification (15)
A40: Break | B40: =C39 | C40: =B40+'Settings and notes'!$C$5/1440
A41: S4 | B41: =C40 | C41: =B41+TIME(1,30,0) | D41: Feeding the catalogue: batch feeds and partner APIs | E41: Demo 25 (+ Demo 24) | F41: Spring Batch: job, step, reader, processor, writer. A supplier CSV or JSON feed imported into the catalogue with validation and a reject file; the price feed into the pricing service with a status endpoint; restartability, chunking, skip policies and scheduling. A shipping-rates partner API through an HTTP interface client with resilience and WireMock contract tests, and how partners authenticate (API keys, client credentials, mTLS). | G41: Lab 1 Spring Batch: job, step, reader, writer (20) Lab 2 The supplier feed, with a reject file (25) Lab 3 The price feed and its status endpoint (15) Lab 4 The shipping partner behind WireMock (20)
A43: Add-on 3 · The Next.js storefront, part 1: foundations, catalogue and search
A44: When | B44: After the core, or on its own
...

Sheet Example packages
A1: Example packages · what each extra day adds
A2: Each row is a complete programme, read left to right. Blue cells are the five core days; every coloured cell is one add-on day. These are suggestions: any combination can be built on the "Build your programme" sheet.
A4: Key | B4: Core Days 1–5
B5: Pre-course: Modern Java for Spring developers (pre-course bridge)
B6: Add-on 1: Microservices in depth: discovery, resilience and observability
B7: Add-on 2: Integrations: Razorpay payments, Resend e-mail and batch feeds
B8: Add-on 3: The Next.js storefront, part 1: foundations, catalogue and search
B9: Add-on 4: The Next.js storefront, part 2: cart, accounts and checkout
B10: Add-on 5: Testing, part 1: unit tests, Spring slices and integration tests
B11: Add-on 6: Testing, part 2: between services, end to end and non-functional
B12: Add-on 7: Docker: containerising the services and the storefront
B13: Add-on 8: Docker Compose: the whole system in one file
B14: Add-on 9: GitHub Actions: CI/CD for the whole system
B15: Add-on 10: Event-driven microservices with Kafka
B16: Add-on 11: Kubernetes: ShopScope on a cluster
... B18: Add-on 13: Production readiness, migration and capstone
A20: Days | B20: Best for | C20: Day 1 | D20: Day 2 | E20: Day 3 | F20: Day 4 | G20: Day 5 | H20: Day 6 | I20: Day 7 | J20: Day 8 | K20: Day 9 | L20: Day 10 | M20: Day 11 | N20: Day 12 | O20: Day 13 | P20: Day 14 | Q20: Day 15 | R20: Day 16 | S20: Day 17 | T20: Day 18 | U20: Day 19
A21: 5 days | B21: Most teams building or maintaining Spring Boot microservices | C21: Core 1 | D21: Core 2 | E21: Core 3 | F21: Core 4 | G21: Core 5
A22: 6 days | B22: Developers coming from Java 8 or another language | C22: Bridge | D22: Core 1 | E22: Core 2 | F22: Core 3 | G22: Core 4 | H22: Core 5
A23: 7 days | B23: Teams running microservices in production | C23: Core 1 | D23: Core 2 | E23: Core 3 | F23: Core 4 | G23: Core 5 | H23: Resilience | I23: Integrations
A24: 7 days | B24: Full-stack teams, or a front-end team joining the back-end track | C24: Core 1 | D24: Core 2 | E24: Core 3 | F24: Core 4 | G24: Core 5 | H24: Storefront 1 | I24: Storefront 2
A25: 7 days | B25: Teams that need a strong quality gate | C25: Core 1 | D25: Core 2 | E25: Core 3 | F25: Core 4 | G25: Core 5 | H25: Testing 1 | I25: Testing 2
A26: 8 days | B26: Teams moving to containers and CI/CD | C26: Core 1 | D26: Core 2 | E26: Core 3 | F26: Core 4 | G26: Core 5 | H26: Docker | I26: Compose | J26: GitHub Actions
A27: 8 days | B27: Teams adding AI features to their services | C27: Core 1 | D27: Core 2 | E27: Core 3 | F27: Core 4 | G27: Core 5 | H27: Resilience | I27: Spring AI | J27: Capstone
A28: 10 days | B28: Cloud-native platform teams | C28: Core 1 | D28: Core 2 | E28: Core 3 | F28: Core 4 | G28: Core 5 | H28: Resilience | I28: Docker | J28: Compose | K28: GitHub Actions | L28: Kubernetes
A29: 12 days | B29: Product teams that own the store end to end | C29: Core 1 | D29: Core 2 | E29: Core 3 | F29: Core 4 | G29: Core 5 | H29: Resilience | I29: Integrations | J29: Storefront 1 | K29: Storefront 2 | L29: Testing 1 | M29: Testing 2 | N29: Capstone
A30: 19 days | B30: The complete programme for a new-to-Spring cohort | C30: Bridge | D30: Core 1 | E30: Core 2 | F30: Core 3 | G30: Core 4 | H30: Core 5 | I30: Resilience | J30: Integrations | K30: Storefront 1 | L30: Storefront 2 | M30: Testing 1 | N30: Testing 2 | O30: Docker | P30: Compose | Q30: GitHub Actions | R30: Kafka & events | S30: Kubernetes | T30: Spring AI | U30: Capstone
A32: Order rules: the bridge always comes before Day 1, and Capstone is always the last day. Storefront part 2 follows part 1, Testing part 2 follows part 1, and Docker comes before Docker Compose, GitHub Actions and Kubernetes. The other add-ons can be taken in any order.

Sheet Settings and notes
A1: Settings and notes
A2: Change the three yellow cells to match your working day: every start and end time in this file follows them.
B4: Day starts at | C4: =TIME(9,0,0) | D4: Default 09:00.
B5: Short break (minutes) | C5: 15 | D5: Two short breaks a day.
B6: Lunch (minutes) | C6: 60 | D6: One lunch break a day.
B8: How to use this file | C8: 1. Read the 5-day core and the add-on days. 2. On "Build your programme", choose Yes for the add-ons you want; the total and the day-by-day programme update. 3. "Example packages" shows common combinations at a glance.
B9: Who it is for | C9: Java developers who know the language basics and object-oriented programming. Teams coming from Java 8 or another language should add the pre-course bridge. The two storefront days are written for front-end developers and need no Java.
B10: How sessions run | C10: One system, ShopScope Commerce (an online store with a storefront, back-end services and real payment and e-mail providers), grows through the whole programme. It starts as a plain-Java monolith with a written register of its problems, and every session removes one of them until the monolith has become microservices. Each session is a short concept block followed by hands-on labs that participants type themselves, starting from a ready-made starter project, so a team that runs over on one lab still starts the next session on time. Every demo comes with study notes and a step-by-step guide.
B11: Environment | C11: JDK 17 or newer (the code compiles for 17 and runs on 21 and 25), IntelliJ IDEA or VS Code, and Docker Desktop (for PostgreSQL, MySQL, MongoDB, Redis, Keycloak and the services). The storefront days need Node 22. Every starter can also run in GitHub Codespaces when local installs are restricted.
B12: Stack | C12: Java 17 baseline (runs on 17, 21, 25), Spring Boot 4 (Spring Framework 7, Spring Security 7, Hibernate 7), Spring Data JPA and Spring Data MongoDB, PostgreSQL, MySQL, MongoDB, Flyway, MapStruct, springdoc OpenAPI, JUnit 5, Testcontainers, Keycloak, Spring Cloud (Config, Eureka, Gateway), Resilience4j, OpenTelemetry, Razorpay, Resend. Storefront: Next.js 16, React 19, TypeScript, Tailwind 4. Add-ons: Playwright, k6, Docker, Compose, GitHub Actions, Kafka, Kubernetes with Helm and Argo CD, Spring AI.
B13: Full-stack option | C13: The storefront days build the same store the back-end days serve, so the programme can run as one full-stack track: back-end developers take the core, front-end developers take the two storefront days, and both teams meet on the same API.
